[2019-03-11 20:28:46 +0000] [2125] [INFO] Starting gunicorn 19.6.0
[2019-03-11 20:28:46 +0000] [2125] [INFO] Listening at: http://0.0.0.0:5000 (2125)
[2019-03-11 20:28:46 +0000] [2125] [INFO] Using worker: sync
[2019-03-11 20:28:46 +0000] [2128] [INFO] Booting worker with pid: 2128
[2019-03-11 20:29:03 +0000] [2125] [INFO] Handling signal: int
[2019-03-11 20:29:03 +0000] [2128] [INFO] Worker exiting (pid: 2128)
[2019-03-11 20:29:03 +0000] [2125] [INFO] Shutting down: Master
[2019-03-12 14:26:49 +0000] [5033] [INFO] Starting gunicorn 19.6.0
[2019-03-12 14:26:49 +0000] [5033] [INFO] Listening at: http://0.0.0.0:5000 (5033)
[2019-03-12 14:26:49 +0000] [5033] [INFO] Using worker: sync
[2019-03-12 14:26:49 +0000] [5036] [INFO] Booting worker with pid: 5036
[2019-03-12 14:28:42 +0000] [5033] [CRITICAL] WORKER TIMEOUT (pid:5036)
[2019-03-12 14:28:42 +0000] [5036] [INFO] Worker exiting (pid: 5036)
[2019-03-12 14:28:42 +0000] [5048] [INFO] Booting worker with pid: 5048
[2019-03-12 14:30:59 +0000] [5033] [CRITICAL] WORKER TIMEOUT (pid:5048)
[2019-03-12 14:30:59 +0000] [5048] [INFO] Worker exiting (pid: 5048)
[2019-03-12 14:30:59 +0000] [5057] [INFO] Booting worker with pid: 5057
[2019-03-12 15:04:27 +0000] [5483] [INFO] Starting gunicorn 19.6.0
[2019-03-12 15:04:27 +0000] [5483] [ERROR] Connection in use: ('0.0.0.0', 5000)
[2019-03-12 15:04:27 +0000] [5483] [ERROR] Retrying in 1 second.
[2019-03-12 15:04:28 +0000] [5483] [ERROR] Connection in use: ('0.0.0.0', 5000)
[2019-03-12 15:04:28 +0000] [5483] [ERROR] Retrying in 1 second.
[2019-03-12 15:04:29 +0000] [5483] [ERROR] Connection in use: ('0.0.0.0', 5000)
[2019-03-12 15:04:29 +0000] [5483] [ERROR] Retrying in 1 second.
[2019-03-12 15:04:30 +0000] [5483] [ERROR] Connection in use: ('0.0.0.0', 5000)
[2019-03-12 15:04:30 +0000] [5483] [ERROR] Retrying in 1 second.
[2019-03-12 15:04:31 +0000] [5483] [ERROR] Connection in use: ('0.0.0.0', 5000)
[2019-03-12 15:04:31 +0000] [5483] [ERROR] Retrying in 1 second.
[2019-03-12 15:04:32 +0000] [5483] [ERROR] Can't connect to ('0.0.0.0', 5000)
[2019-03-12 15:05:25 +0000] [5497] [INFO] Starting gunicorn 19.6.0
[2019-03-12 15:05:25 +0000] [5497] [ERROR] Connection in use: ('0.0.0.0', 5000)
[2019-03-12 15:05:25 +0000] [5497] [ERROR] Retrying in 1 second.
[2019-03-12 15:05:26 +0000] [5497] [ERROR] Connection in use: ('0.0.0.0', 5000)
[2019-03-12 15:05:26 +0000] [5497] [ERROR] Retrying in 1 second.
[2019-03-12 15:05:27 +0000] [5497] [ERROR] Connection in use: ('0.0.0.0', 5000)
[2019-03-12 15:05:27 +0000] [5497] [ERROR] Retrying in 1 second.
[2019-03-12 15:05:28 +0000] [5497] [ERROR] Connection in use: ('0.0.0.0', 5000)
[2019-03-12 15:05:28 +0000] [5497] [ERROR] Retrying in 1 second.
[2019-03-12 15:05:29 +0000] [5497] [ERROR] Connection in use: ('0.0.0.0', 5000)
[2019-03-12 15:05:29 +0000] [5497] [ERROR] Retrying in 1 second.
[2019-03-12 15:05:30 +0000] [5497] [ERROR] Can't connect to ('0.0.0.0', 5000)
[2019-03-12 15:06:01 +0000] [5504] [INFO] Starting gunicorn 19.6.0
[2019-03-12 15:06:01 +0000] [5504] [ERROR] Connection in use: ('0.0.0.0', 5000)
[2019-03-12 15:06:01 +0000] [5504] [ERROR] Retrying in 1 second.
[2019-03-12 15:06:02 +0000] [5504] [ERROR] Connection in use: ('0.0.0.0', 5000)
[2019-03-12 15:06:02 +0000] [5504] [ERROR] Retrying in 1 second.
[2019-03-12 15:06:03 +0000] [5504] [ERROR] Connection in use: ('0.0.0.0', 5000)
[2019-03-12 15:06:03 +0000] [5504] [ERROR] Retrying in 1 second.
[2019-03-12 15:06:04 +0000] [5504] [ERROR] Connection in use: ('0.0.0.0', 5000)
[2019-03-12 15:06:04 +0000] [5504] [ERROR] Retrying in 1 second.
[2019-03-12 15:06:05 +0000] [5504] [ERROR] Connection in use: ('0.0.0.0', 5000)
[2019-03-12 15:06:05 +0000] [5504] [ERROR] Retrying in 1 second.
[2019-03-12 15:06:06 +0000] [5504] [ERROR] Can't connect to ('0.0.0.0', 5000)
[2019-03-12 15:18:24 +0000] [5667] [INFO] Starting gunicorn 19.6.0
[2019-03-12 15:18:24 +0000] [5667] [ERROR] Connection in use: ('0.0.0.0', 5000)
[2019-03-12 15:18:24 +0000] [5667] [ERROR] Retrying in 1 second.
[2019-03-12 15:18:25 +0000] [5667] [ERROR] Connection in use: ('0.0.0.0', 5000)
[2019-03-12 15:18:25 +0000] [5667] [ERROR] Retrying in 1 second.
[2019-03-12 15:18:26 +0000] [5667] [ERROR] Connection in use: ('0.0.0.0', 5000)
[2019-03-12 15:18:26 +0000] [5667] [ERROR] Retrying in 1 second.
[2019-03-12 15:18:27 +0000] [5667] [ERROR] Connection in use: ('0.0.0.0', 5000)
[2019-03-12 15:18:27 +0000] [5667] [ERROR] Retrying in 1 second.
[2019-03-12 15:18:28 +0000] [5667] [ERROR] Connection in use: ('0.0.0.0', 5000)
[2019-03-12 15:18:28 +0000] [5667] [ERROR] Retrying in 1 second.
[2019-03-12 15:18:29 +0000] [5667] [ERROR] Can't connect to ('0.0.0.0', 5000)
[2019-03-12 15:19:11 +0000] [5033] [CRITICAL] WORKER TIMEOUT (pid:5057)
[2019-03-12 15:19:11 +0000] [5057] [INFO] Worker exiting (pid: 5057)
[2019-03-12 15:19:11 +0000] [5672] [INFO] Booting worker with pid: 5672
[2019-03-12 15:19:29,006] ERROR in app: Exception on /s3/delete [POST]
Traceback (most recent call last):
  File "/home/ubuntu/Desktop/ece1779/databases/venv/lib/python3.5/site-packages/flask/app.py", line 1982, in wsgi_app
    response = self.full_dispatch_request()
  File "/home/ubuntu/Desktop/ece1779/databases/venv/lib/python3.5/site-packages/flask/app.py", line 1614, in full_dispatch_request
    rv = self.handle_user_exception(e)
  File "/home/ubuntu/Desktop/ece1779/databases/venv/lib/python3.5/site-packages/flask/app.py", line 1517, in handle_user_exception
    reraise(exc_type, exc_value, tb)
  File "/home/ubuntu/Desktop/ece1779/databases/venv/lib/python3.5/site-packages/flask/_compat.py", line 33, in reraise
    raise value
  File "/home/ubuntu/Desktop/ece1779/databases/venv/lib/python3.5/site-packages/flask/app.py", line 1612, in full_dispatch_request
    rv = self.dispatch_request()
  File "/home/ubuntu/Desktop/ece1779/databases/venv/lib/python3.5/site-packages/flask/app.py", line 1598, in dispatch_request
    return self.view_functions[rule.endpoint](**req.view_args)
  File "/home/ubuntu/Desktop/ece1779/manager_UI/app/workers.py", line 173, in delete
    cursor.execute("""TRUNCATE TABLE photo""")
  File "/home/ubuntu/Desktop/ece1779/databases/venv/lib/python3.5/site-packages/mysql/connector/cursor.py", line 552, in execute
    self._handle_result(self._connection.cmd_query(stmt))
  File "/home/ubuntu/Desktop/ece1779/databases/venv/lib/python3.5/site-packages/mysql/connector/connection.py", line 490, in cmd_query
    result = self._handle_result(self._send_cmd(ServerCmd.QUERY, query))
  File "/home/ubuntu/Desktop/ece1779/databases/venv/lib/python3.5/site-packages/mysql/connector/connection.py", line 395, in _handle_result
    raise errors.get_exception(packet)
mysql.connector.errors.ProgrammingError: 1146 (42S02): Table 'ece1779.photo' doesn't exist
[2019-03-12 15:20:45 +0000] [5676] [INFO] Booting worker with pid: 5676
[2019-03-12 15:20:45 +0000] [5033] [INFO] Handling signal: hup
[2019-03-12 15:20:45 +0000] [5033] [INFO] Hang up: Master
[2019-03-12 15:20:45 +0000] [5033] [INFO] Handling signal: hup
[2019-03-12 15:20:45 +0000] [5033] [INFO] Hang up: Master
[2019-03-12 15:20:45 +0000] [5677] [INFO] Booting worker with pid: 5677
[2019-03-12 15:20:45 +0000] [5678] [INFO] Booting worker with pid: 5678
[2019-03-12 15:20:45 +0000] [5676] [INFO] Worker exiting (pid: 5676)
[2019-03-12 15:20:46 +0000] [5677] [INFO] Worker exiting (pid: 5677)
[2019-03-12 15:26:56 +0000] [5731] [INFO] Starting gunicorn 19.6.0
[2019-03-12 15:26:56 +0000] [5731] [ERROR] Connection in use: ('0.0.0.0', 5000)
[2019-03-12 15:26:56 +0000] [5731] [ERROR] Retrying in 1 second.
[2019-03-12 15:26:57 +0000] [5731] [ERROR] Connection in use: ('0.0.0.0', 5000)
[2019-03-12 15:26:57 +0000] [5731] [ERROR] Retrying in 1 second.
[2019-03-12 15:26:58 +0000] [5731] [ERROR] Connection in use: ('0.0.0.0', 5000)
[2019-03-12 15:26:58 +0000] [5731] [ERROR] Retrying in 1 second.
[2019-03-12 15:26:59 +0000] [5731] [ERROR] Connection in use: ('0.0.0.0', 5000)
[2019-03-12 15:26:59 +0000] [5731] [ERROR] Retrying in 1 second.
[2019-03-12 15:27:00 +0000] [5731] [ERROR] Connection in use: ('0.0.0.0', 5000)
[2019-03-12 15:27:00 +0000] [5731] [ERROR] Retrying in 1 second.
[2019-03-12 15:27:01 +0000] [5731] [ERROR] Can't connect to ('0.0.0.0', 5000)
[2019-03-12 15:27:27 +0000] [5736] [INFO] Starting gunicorn 19.6.0
[2019-03-12 15:27:27 +0000] [5736] [ERROR] Connection in use: ('0.0.0.0', 5000)
[2019-03-12 15:27:27 +0000] [5736] [ERROR] Retrying in 1 second.
[2019-03-12 15:27:28 +0000] [5736] [ERROR] Connection in use: ('0.0.0.0', 5000)
[2019-03-12 15:27:28 +0000] [5736] [ERROR] Retrying in 1 second.
[2019-03-12 15:27:29 +0000] [5736] [ERROR] Connection in use: ('0.0.0.0', 5000)
[2019-03-12 15:27:29 +0000] [5736] [ERROR] Retrying in 1 second.
[2019-03-12 15:27:30 +0000] [5736] [ERROR] Connection in use: ('0.0.0.0', 5000)
[2019-03-12 15:27:30 +0000] [5736] [ERROR] Retrying in 1 second.
[2019-03-12 15:27:31 +0000] [5736] [ERROR] Connection in use: ('0.0.0.0', 5000)
[2019-03-12 15:27:31 +0000] [5736] [ERROR] Retrying in 1 second.
[2019-03-12 15:27:31,440] ERROR in app: Exception on /s3/delete [POST]
Traceback (most recent call last):
  File "/home/ubuntu/Desktop/ece1779/databases/venv/lib/python3.5/site-packages/flask/app.py", line 1982, in wsgi_app
    response = self.full_dispatch_request()
  File "/home/ubuntu/Desktop/ece1779/databases/venv/lib/python3.5/site-packages/flask/app.py", line 1614, in full_dispatch_request
    rv = self.handle_user_exception(e)
  File "/home/ubuntu/Desktop/ece1779/databases/venv/lib/python3.5/site-packages/flask/app.py", line 1517, in handle_user_exception
    reraise(exc_type, exc_value, tb)
  File "/home/ubuntu/Desktop/ece1779/databases/venv/lib/python3.5/site-packages/flask/_compat.py", line 33, in reraise
    raise value
  File "/home/ubuntu/Desktop/ece1779/databases/venv/lib/python3.5/site-packages/flask/app.py", line 1612, in full_dispatch_request
    rv = self.dispatch_request()
  File "/home/ubuntu/Desktop/ece1779/databases/venv/lib/python3.5/site-packages/flask/app.py", line 1598, in dispatch_request
    return self.view_functions[rule.endpoint](**req.view_args)
  File "/home/ubuntu/Desktop/ece1779/manager_UI/app/workers.py", line 157, in delete
    print(image_name)
OSError: [Errno 5] Input/output error
[2019-03-12 15:27:32 +0000] [5736] [ERROR] Can't connect to ('0.0.0.0', 5000)
[2019-03-12 15:27:38,118] ERROR in app: Exception on /ec2_worker [GET]
Traceback (most recent call last):
  File "/home/ubuntu/Desktop/ece1779/databases/venv/lib/python3.5/site-packages/flask/app.py", line 1982, in wsgi_app
    response = self.full_dispatch_request()
  File "/home/ubuntu/Desktop/ece1779/databases/venv/lib/python3.5/site-packages/flask/app.py", line 1614, in full_dispatch_request
    rv = self.handle_user_exception(e)
  File "/home/ubuntu/Desktop/ece1779/databases/venv/lib/python3.5/site-packages/flask/app.py", line 1517, in handle_user_exception
    reraise(exc_type, exc_value, tb)
  File "/home/ubuntu/Desktop/ece1779/databases/venv/lib/python3.5/site-packages/flask/_compat.py", line 33, in reraise
    raise value
  File "/home/ubuntu/Desktop/ece1779/databases/venv/lib/python3.5/site-packages/flask/app.py", line 1612, in full_dispatch_request
    rv = self.dispatch_request()
  File "/home/ubuntu/Desktop/ece1779/databases/venv/lib/python3.5/site-packages/flask/app.py", line 1598, in dispatch_request
    return self.view_functions[rule.endpoint](**req.view_args)
  File "/home/ubuntu/Desktop/ece1779/manager_UI/app/workers.py", line 64, in ec2_list
    print(instance.id, instance.image_id, instance.key_name, instance.tags)
OSError: [Errno 5] Input/output error
[2019-03-12 15:27:46 +0000] [5740] [INFO] Starting gunicorn 19.6.0
[2019-03-12 15:27:46 +0000] [5740] [ERROR] Connection in use: ('0.0.0.0', 5000)
[2019-03-12 15:27:46 +0000] [5740] [ERROR] Retrying in 1 second.
[2019-03-12 15:27:47 +0000] [5740] [ERROR] Connection in use: ('0.0.0.0', 5000)
[2019-03-12 15:27:47 +0000] [5740] [ERROR] Retrying in 1 second.
[2019-03-12 15:27:48 +0000] [5740] [ERROR] Connection in use: ('0.0.0.0', 5000)
[2019-03-12 15:27:48 +0000] [5740] [ERROR] Retrying in 1 second.
[2019-03-12 15:27:49 +0000] [5740] [ERROR] Connection in use: ('0.0.0.0', 5000)
[2019-03-12 15:27:49 +0000] [5740] [ERROR] Retrying in 1 second.
[2019-03-12 15:27:50 +0000] [5740] [ERROR] Connection in use: ('0.0.0.0', 5000)
[2019-03-12 15:27:50 +0000] [5740] [ERROR] Retrying in 1 second.
[2019-03-12 15:27:51 +0000] [5740] [ERROR] Can't connect to ('0.0.0.0', 5000)
[2019-03-12 15:27:52,469] ERROR in app: Exception on /ec2_worker [GET]
Traceback (most recent call last):
  File "/home/ubuntu/Desktop/ece1779/databases/venv/lib/python3.5/site-packages/flask/app.py", line 1982, in wsgi_app
    response = self.full_dispatch_request()
  File "/home/ubuntu/Desktop/ece1779/databases/venv/lib/python3.5/site-packages/flask/app.py", line 1614, in full_dispatch_request
    rv = self.handle_user_exception(e)
  File "/home/ubuntu/Desktop/ece1779/databases/venv/lib/python3.5/site-packages/flask/app.py", line 1517, in handle_user_exception
    reraise(exc_type, exc_value, tb)
  File "/home/ubuntu/Desktop/ece1779/databases/venv/lib/python3.5/site-packages/flask/_compat.py", line 33, in reraise
    raise value
  File "/home/ubuntu/Desktop/ece1779/databases/venv/lib/python3.5/site-packages/flask/app.py", line 1612, in full_dispatch_request
    rv = self.dispatch_request()
  File "/home/ubuntu/Desktop/ece1779/databases/venv/lib/python3.5/site-packages/flask/app.py", line 1598, in dispatch_request
    return self.view_functions[rule.endpoint](**req.view_args)
  File "/home/ubuntu/Desktop/ece1779/manager_UI/app/workers.py", line 64, in ec2_list
    print(instance.id, instance.image_id, instance.key_name, instance.tags)
OSError: [Errno 5] Input/output error
[2019-03-12 15:28:22 +0000] [5033] [CRITICAL] WORKER TIMEOUT (pid:5678)
[2019-03-12 15:28:22 +0000] [5678] [INFO] Worker exiting (pid: 5678)
[2019-03-12 15:28:22 +0000] [5748] [INFO] Booting worker with pid: 5748
[2019-03-12 15:28:36 +0000] [5752] [INFO] Starting gunicorn 19.6.0
[2019-03-12 15:28:36 +0000] [5752] [ERROR] Connection in use: ('0.0.0.0', 5000)
[2019-03-12 15:28:36 +0000] [5752] [ERROR] Retrying in 1 second.
[2019-03-12 15:28:37 +0000] [5752] [ERROR] Connection in use: ('0.0.0.0', 5000)
[2019-03-12 15:28:37 +0000] [5752] [ERROR] Retrying in 1 second.
[2019-03-12 15:28:38 +0000] [5752] [ERROR] Connection in use: ('0.0.0.0', 5000)
[2019-03-12 15:28:38 +0000] [5752] [ERROR] Retrying in 1 second.
[2019-03-12 15:28:39 +0000] [5752] [ERROR] Connection in use: ('0.0.0.0', 5000)
[2019-03-12 15:28:39 +0000] [5752] [ERROR] Retrying in 1 second.
[2019-03-12 15:28:40 +0000] [5752] [ERROR] Connection in use: ('0.0.0.0', 5000)
[2019-03-12 15:28:40 +0000] [5752] [ERROR] Retrying in 1 second.
[2019-03-12 15:28:41 +0000] [5752] [ERROR] Can't connect to ('0.0.0.0', 5000)
[2019-03-12 15:28:44,733] ERROR in app: Exception on /ec2_worker [GET]
Traceback (most recent call last):
  File "/home/ubuntu/Desktop/ece1779/databases/venv/lib/python3.5/site-packages/flask/app.py", line 1982, in wsgi_app
    response = self.full_dispatch_request()
  File "/home/ubuntu/Desktop/ece1779/databases/venv/lib/python3.5/site-packages/flask/app.py", line 1614, in full_dispatch_request
    rv = self.handle_user_exception(e)
  File "/home/ubuntu/Desktop/ece1779/databases/venv/lib/python3.5/site-packages/flask/app.py", line 1517, in handle_user_exception
    reraise(exc_type, exc_value, tb)
  File "/home/ubuntu/Desktop/ece1779/databases/venv/lib/python3.5/site-packages/flask/_compat.py", line 33, in reraise
    raise value
  File "/home/ubuntu/Desktop/ece1779/databases/venv/lib/python3.5/site-packages/flask/app.py", line 1612, in full_dispatch_request
    rv = self.dispatch_request()
  File "/home/ubuntu/Desktop/ece1779/databases/venv/lib/python3.5/site-packages/flask/app.py", line 1598, in dispatch_request
    return self.view_functions[rule.endpoint](**req.view_args)
  File "/home/ubuntu/Desktop/ece1779/manager_UI/app/workers.py", line 64, in ec2_list
    print(instance.id, instance.image_id, instance.key_name, instance.tags)
OSError: [Errno 5] Input/output error
[2019-03-12 15:29:14 +0000] [5033] [CRITICAL] WORKER TIMEOUT (pid:5748)
[2019-03-12 15:29:14 +0000] [5748] [INFO] Worker exiting (pid: 5748)
[2019-03-12 15:29:14 +0000] [5757] [INFO] Booting worker with pid: 5757
[2019-03-12 15:31:18 +0000] [5862] [INFO] Starting gunicorn 19.6.0
[2019-03-12 15:31:18 +0000] [5862] [ERROR] Connection in use: ('0.0.0.0', 5000)
[2019-03-12 15:31:18 +0000] [5862] [ERROR] Retrying in 1 second.
[2019-03-12 15:31:19 +0000] [5862] [ERROR] Connection in use: ('0.0.0.0', 5000)
[2019-03-12 15:31:19 +0000] [5862] [ERROR] Retrying in 1 second.
[2019-03-12 15:31:20 +0000] [5862] [ERROR] Connection in use: ('0.0.0.0', 5000)
[2019-03-12 15:31:20 +0000] [5862] [ERROR] Retrying in 1 second.
[2019-03-12 15:31:21 +0000] [5862] [ERROR] Connection in use: ('0.0.0.0', 5000)
[2019-03-12 15:31:21 +0000] [5862] [ERROR] Retrying in 1 second.
[2019-03-12 15:31:22 +0000] [5862] [ERROR] Connection in use: ('0.0.0.0', 5000)
[2019-03-12 15:31:22 +0000] [5862] [ERROR] Retrying in 1 second.
[2019-03-12 15:31:23 +0000] [5862] [ERROR] Can't connect to ('0.0.0.0', 5000)
[2019-03-12 15:31:48,443] ERROR in app: Exception on /ec2_worker [GET]
Traceback (most recent call last):
  File "/home/ubuntu/Desktop/ece1779/databases/venv/lib/python3.5/site-packages/flask/app.py", line 1982, in wsgi_app
    response = self.full_dispatch_request()
  File "/home/ubuntu/Desktop/ece1779/databases/venv/lib/python3.5/site-packages/flask/app.py", line 1614, in full_dispatch_request
    rv = self.handle_user_exception(e)
  File "/home/ubuntu/Desktop/ece1779/databases/venv/lib/python3.5/site-packages/flask/app.py", line 1517, in handle_user_exception
    reraise(exc_type, exc_value, tb)
  File "/home/ubuntu/Desktop/ece1779/databases/venv/lib/python3.5/site-packages/flask/_compat.py", line 33, in reraise
    raise value
  File "/home/ubuntu/Desktop/ece1779/databases/venv/lib/python3.5/site-packages/flask/app.py", line 1612, in full_dispatch_request
    rv = self.dispatch_request()
  File "/home/ubuntu/Desktop/ece1779/databases/venv/lib/python3.5/site-packages/flask/app.py", line 1598, in dispatch_request
    return self.view_functions[rule.endpoint](**req.view_args)
  File "/home/ubuntu/Desktop/ece1779/manager_UI/app/workers.py", line 64, in ec2_list
    print(instance.id, instance.image_id, instance.key_name, instance.tags)
OSError: [Errno 5] Input/output error
[2019-03-12 15:32:19 +0000] [5033] [CRITICAL] WORKER TIMEOUT (pid:5757)
[2019-03-12 15:32:19 +0000] [5757] [INFO] Worker exiting (pid: 5757)
[2019-03-12 15:32:19 +0000] [5916] [INFO] Booting worker with pid: 5916
[2019-03-12 15:36:33 +0000] [5033] [INFO] Handling signal: term
[2019-03-12 15:36:33 +0000] [5916] [INFO] Worker exiting (pid: 5916)
[2019-03-12 15:36:33 +0000] [5033] [INFO] Shutting down: Master
[2019-03-12 15:37:25 +0000] [5948] [INFO] Starting gunicorn 19.6.0
[2019-03-12 15:37:25 +0000] [5948] [INFO] Listening at: http://0.0.0.0:5000 (5948)
[2019-03-12 15:37:25 +0000] [5948] [INFO] Using worker: sync
[2019-03-12 15:37:25 +0000] [5951] [INFO] Booting worker with pid: 5951
[2019-03-12 15:37:45,867] ERROR in app: Exception on /s3/delete [POST]
Traceback (most recent call last):
  File "/home/ubuntu/Desktop/ece1779/databases/venv/lib/python3.5/site-packages/flask/app.py", line 1982, in wsgi_app
    response = self.full_dispatch_request()
  File "/home/ubuntu/Desktop/ece1779/databases/venv/lib/python3.5/site-packages/flask/app.py", line 1614, in full_dispatch_request
    rv = self.handle_user_exception(e)
  File "/home/ubuntu/Desktop/ece1779/databases/venv/lib/python3.5/site-packages/flask/app.py", line 1517, in handle_user_exception
    reraise(exc_type, exc_value, tb)
  File "/home/ubuntu/Desktop/ece1779/databases/venv/lib/python3.5/site-packages/flask/_compat.py", line 33, in reraise
    raise value
  File "/home/ubuntu/Desktop/ece1779/databases/venv/lib/python3.5/site-packages/flask/app.py", line 1612, in full_dispatch_request
    rv = self.dispatch_request()
  File "/home/ubuntu/Desktop/ece1779/databases/venv/lib/python3.5/site-packages/flask/app.py", line 1598, in dispatch_request
    return self.view_functions[rule.endpoint](**req.view_args)
  File "/home/ubuntu/Desktop/ece1779/manager_UI/app/workers.py", line 168, in delete
    cursor.execute("""DELETE FROM photo WHERE id != 0""")
  File "/home/ubuntu/Desktop/ece1779/databases/venv/lib/python3.5/site-packages/mysql/connector/cursor.py", line 552, in execute
    self._handle_result(self._connection.cmd_query(stmt))
  File "/home/ubuntu/Desktop/ece1779/databases/venv/lib/python3.5/site-packages/mysql/connector/connection.py", line 490, in cmd_query
    result = self._handle_result(self._send_cmd(ServerCmd.QUERY, query))
  File "/home/ubuntu/Desktop/ece1779/databases/venv/lib/python3.5/site-packages/mysql/connector/connection.py", line 395, in _handle_result
    raise errors.get_exception(packet)
mysql.connector.errors.ProgrammingError: 1146 (42S02): Table 'ece1779.photo' doesn't exist
[2019-03-12 15:38:41 +0000] [5948] [INFO] Handling signal: int
[2019-03-12 15:38:42 +0000] [5951] [INFO] Worker exiting (pid: 5951)
[2019-03-12 15:38:42 +0000] [5948] [INFO] Shutting down: Master
[2019-03-12 15:59:33 +0000] [6398] [INFO] Starting gunicorn 19.6.0
[2019-03-12 15:59:33 +0000] [6398] [INFO] Listening at: http://0.0.0.0:5000 (6398)
[2019-03-12 15:59:33 +0000] [6398] [INFO] Using worker: sync
[2019-03-12 15:59:33 +0000] [6401] [INFO] Booting worker with pid: 6401
[2019-03-12 16:00:29 +0000] [6398] [INFO] Handling signal: int
[2019-03-12 16:00:29 +0000] [6401] [INFO] Worker exiting (pid: 6401)
[2019-03-12 16:00:29 +0000] [6398] [INFO] Shutting down: Master
[2019-03-12 16:45:31 +0000] [6705] [INFO] Starting gunicorn 19.6.0
[2019-03-12 16:45:31 +0000] [6705] [INFO] Listening at: http://0.0.0.0:5000 (6705)
[2019-03-12 16:45:31 +0000] [6705] [INFO] Using worker: sync
[2019-03-12 16:45:31 +0000] [6708] [INFO] Booting worker with pid: 6708
[2019-03-12 16:45:40,455] ERROR in app: Exception on /ec2_worker/i-073bb9dc0fa33d685 [GET]
Traceback (most recent call last):
  File "/home/ubuntu/Desktop/ece1779/databases/venv/lib/python3.5/site-packages/flask/app.py", line 1982, in wsgi_app
    response = self.full_dispatch_request()
  File "/home/ubuntu/Desktop/ece1779/databases/venv/lib/python3.5/site-packages/flask/app.py", line 1614, in full_dispatch_request
    rv = self.handle_user_exception(e)
  File "/home/ubuntu/Desktop/ece1779/databases/venv/lib/python3.5/site-packages/flask/app.py", line 1517, in handle_user_exception
    reraise(exc_type, exc_value, tb)
  File "/home/ubuntu/Desktop/ece1779/databases/venv/lib/python3.5/site-packages/flask/_compat.py", line 33, in reraise
    raise value
  File "/home/ubuntu/Desktop/ece1779/databases/venv/lib/python3.5/site-packages/flask/app.py", line 1612, in full_dispatch_request
    rv = self.dispatch_request()
  File "/home/ubuntu/Desktop/ece1779/databases/venv/lib/python3.5/site-packages/flask/app.py", line 1598, in dispatch_request
    return self.view_functions[rule.endpoint](**req.view_args)
  File "/home/ubuntu/Desktop/ece1779/manager_UI/app/workers.py", line 113, in ec2_view
    statistics = ['sum']
  File "/home/ubuntu/Desktop/ece1779/databases/venv/lib/python3.5/site-packages/botocore/client.py", line 357, in _api_call
    return self._make_api_call(operation_name, kwargs)
  File "/home/ubuntu/Desktop/ece1779/databases/venv/lib/python3.5/site-packages/botocore/client.py", line 634, in _make_api_call
    api_params, operation_model, context=request_context)
  File "/home/ubuntu/Desktop/ece1779/databases/venv/lib/python3.5/site-packages/botocore/client.py", line 682, in _convert_to_request_dict
    api_params, operation_model)
  File "/home/ubuntu/Desktop/ece1779/databases/venv/lib/python3.5/site-packages/botocore/validate.py", line 297, in serialize_to_request
    raise ParamValidationError(report=report.generate_report())
botocore.exceptions.ParamValidationError: Parameter validation failed:
Unknown parameter in input: "statistics", must be one of: Namespace, MetricName, Dimensions, StartTime, EndTime, Period, Statistics, ExtendedStatistics, Unit
Unknown parameter in input: "Dimension", must be one of: Namespace, MetricName, Dimensions, StartTime, EndTime, Period, Statistics, ExtendedStatistics, Unit
[2019-03-12 16:46:30,772] ERROR in app: Exception on /ec2_worker/i-0f7ef9cf5ba9f3abd [GET]
Traceback (most recent call last):
  File "/home/ubuntu/Desktop/ece1779/databases/venv/lib/python3.5/site-packages/flask/app.py", line 1982, in wsgi_app
    response = self.full_dispatch_request()
  File "/home/ubuntu/Desktop/ece1779/databases/venv/lib/python3.5/site-packages/flask/app.py", line 1614, in full_dispatch_request
    rv = self.handle_user_exception(e)
  File "/home/ubuntu/Desktop/ece1779/databases/venv/lib/python3.5/site-packages/flask/app.py", line 1517, in handle_user_exception
    reraise(exc_type, exc_value, tb)
  File "/home/ubuntu/Desktop/ece1779/databases/venv/lib/python3.5/site-packages/flask/_compat.py", line 33, in reraise
    raise value
  File "/home/ubuntu/Desktop/ece1779/databases/venv/lib/python3.5/site-packages/flask/app.py", line 1612, in full_dispatch_request
    rv = self.dispatch_request()
  File "/home/ubuntu/Desktop/ece1779/databases/venv/lib/python3.5/site-packages/flask/app.py", line 1598, in dispatch_request
    return self.view_functions[rule.endpoint](**req.view_args)
  File "/home/ubuntu/Desktop/ece1779/manager_UI/app/workers.py", line 113, in ec2_view
    statistics = ['sum']
  File "/home/ubuntu/Desktop/ece1779/databases/venv/lib/python3.5/site-packages/botocore/client.py", line 357, in _api_call
    return self._make_api_call(operation_name, kwargs)
  File "/home/ubuntu/Desktop/ece1779/databases/venv/lib/python3.5/site-packages/botocore/client.py", line 634, in _make_api_call
    api_params, operation_model, context=request_context)
  File "/home/ubuntu/Desktop/ece1779/databases/venv/lib/python3.5/site-packages/botocore/client.py", line 682, in _convert_to_request_dict
    api_params, operation_model)
  File "/home/ubuntu/Desktop/ece1779/databases/venv/lib/python3.5/site-packages/botocore/validate.py", line 297, in serialize_to_request
    raise ParamValidationError(report=report.generate_report())
botocore.exceptions.ParamValidationError: Parameter validation failed:
Unknown parameter in input: "statistics", must be one of: Namespace, MetricName, Dimensions, StartTime, EndTime, Period, Statistics, ExtendedStatistics, Unit
Unknown parameter in input: "Dimension", must be one of: Namespace, MetricName, Dimensions, StartTime, EndTime, Period, Statistics, ExtendedStatistics, Unit
[2019-03-12 16:46:47 +0000] [6705] [INFO] Handling signal: int
[2019-03-12 16:46:47 +0000] [6708] [INFO] Worker exiting (pid: 6708)
[2019-03-12 16:46:47 +0000] [6705] [INFO] Shutting down: Master
[2019-03-12 16:47:08 +0000] [6722] [INFO] Starting gunicorn 19.6.0
[2019-03-12 16:47:08 +0000] [6722] [INFO] Listening at: http://0.0.0.0:5000 (6722)
[2019-03-12 16:47:08 +0000] [6722] [INFO] Using worker: sync
[2019-03-12 16:47:08 +0000] [6725] [INFO] Booting worker with pid: 6725
[2019-03-12 16:47:31 +0000] [6722] [INFO] Handling signal: int
[2019-03-12 16:47:31 +0000] [6725] [INFO] Worker exiting (pid: 6725)
[2019-03-12 16:47:31 +0000] [6722] [INFO] Shutting down: Master
[2019-03-12 16:48:48 +0000] [6752] [INFO] Starting gunicorn 19.6.0
[2019-03-12 16:48:48 +0000] [6752] [INFO] Listening at: http://0.0.0.0:5000 (6752)
[2019-03-12 16:48:48 +0000] [6752] [INFO] Using worker: sync
[2019-03-12 16:48:48 +0000] [6755] [INFO] Booting worker with pid: 6755
[2019-03-12 16:48:53,390] ERROR in app: Exception on /ec2_worker/i-0f7ef9cf5ba9f3abd [GET]
Traceback (most recent call last):
  File "/home/ubuntu/Desktop/ece1779/databases/venv/lib/python3.5/site-packages/flask/app.py", line 1982, in wsgi_app
    response = self.full_dispatch_request()
  File "/home/ubuntu/Desktop/ece1779/databases/venv/lib/python3.5/site-packages/flask/app.py", line 1614, in full_dispatch_request
    rv = self.handle_user_exception(e)
  File "/home/ubuntu/Desktop/ece1779/databases/venv/lib/python3.5/site-packages/flask/app.py", line 1517, in handle_user_exception
    reraise(exc_type, exc_value, tb)
  File "/home/ubuntu/Desktop/ece1779/databases/venv/lib/python3.5/site-packages/flask/_compat.py", line 33, in reraise
    raise value
  File "/home/ubuntu/Desktop/ece1779/databases/venv/lib/python3.5/site-packages/flask/app.py", line 1612, in full_dispatch_request
    rv = self.dispatch_request()
  File "/home/ubuntu/Desktop/ece1779/databases/venv/lib/python3.5/site-packages/flask/app.py", line 1598, in dispatch_request
    return self.view_functions[rule.endpoint](**req.view_args)
  File "/home/ubuntu/Desktop/ece1779/manager_UI/app/workers.py", line 115, in ec2_view
    statistics = ['sum']
  File "/home/ubuntu/Desktop/ece1779/databases/venv/lib/python3.5/site-packages/botocore/client.py", line 357, in _api_call
    return self._make_api_call(operation_name, kwargs)
  File "/home/ubuntu/Desktop/ece1779/databases/venv/lib/python3.5/site-packages/botocore/client.py", line 634, in _make_api_call
    api_params, operation_model, context=request_context)
  File "/home/ubuntu/Desktop/ece1779/databases/venv/lib/python3.5/site-packages/botocore/client.py", line 682, in _convert_to_request_dict
    api_params, operation_model)
  File "/home/ubuntu/Desktop/ece1779/databases/venv/lib/python3.5/site-packages/botocore/validate.py", line 297, in serialize_to_request
    raise ParamValidationError(report=report.generate_report())
botocore.exceptions.ParamValidationError: Parameter validation failed:
Unknown parameter in input: "statistics", must be one of: Namespace, MetricName, Dimensions, StartTime, EndTime, Period, Statistics, ExtendedStatistics, Unit
Unknown parameter in input: "Dimension", must be one of: Namespace, MetricName, Dimensions, StartTime, EndTime, Period, Statistics, ExtendedStatistics, Unit
[2019-03-12 16:49:46 +0000] [6752] [INFO] Handling signal: int
[2019-03-12 16:49:47 +0000] [6755] [INFO] Worker exiting (pid: 6755)
[2019-03-12 16:49:47 +0000] [6752] [INFO] Shutting down: Master
[2019-03-12 16:49:57 +0000] [6768] [INFO] Starting gunicorn 19.6.0
[2019-03-12 16:49:57 +0000] [6768] [INFO] Listening at: http://0.0.0.0:5000 (6768)
[2019-03-12 16:49:57 +0000] [6768] [INFO] Using worker: sync
[2019-03-12 16:49:57 +0000] [6771] [INFO] Booting worker with pid: 6771
[2019-03-12 16:50:32 +0000] [6768] [CRITICAL] WORKER TIMEOUT (pid:6771)
[2019-03-12 16:50:32 +0000] [6771] [INFO] Worker exiting (pid: 6771)
[2019-03-12 16:50:32 +0000] [6775] [INFO] Booting worker with pid: 6775
[2019-03-12 16:54:42 +0000] [6768] [CRITICAL] WORKER TIMEOUT (pid:6775)
[2019-03-12 16:54:42 +0000] [6775] [INFO] Worker exiting (pid: 6775)
[2019-03-12 16:54:42 +0000] [6812] [INFO] Booting worker with pid: 6812
[2019-03-12 16:55:07 +0000] [6768] [INFO] Handling signal: int
[2019-03-12 16:55:07 +0000] [6812] [INFO] Worker exiting (pid: 6812)
[2019-03-12 16:55:08 +0000] [6768] [INFO] Shutting down: Master
[2019-03-12 16:55:19 +0000] [6826] [INFO] Starting gunicorn 19.6.0
[2019-03-12 16:55:19 +0000] [6826] [INFO] Listening at: http://0.0.0.0:5000 (6826)
[2019-03-12 16:55:19 +0000] [6826] [INFO] Using worker: sync
[2019-03-12 16:55:19 +0000] [6829] [INFO] Booting worker with pid: 6829
[2019-03-12 16:56:39 +0000] [6826] [CRITICAL] WORKER TIMEOUT (pid:6829)
[2019-03-12 16:56:39 +0000] [6829] [INFO] Worker exiting (pid: 6829)
[2019-03-12 16:56:39 +0000] [6842] [INFO] Booting worker with pid: 6842
[2019-03-12 16:56:39 +0000] [6842] [ERROR] Exception in worker process
Traceback (most recent call last):
  File "/home/ubuntu/Desktop/ece1779/databases/venv/lib/python3.5/site-packages/gunicorn/arbiter.py", line 557, in spawn_worker
    worker.init_process()
  File "/home/ubuntu/Desktop/ece1779/databases/venv/lib/python3.5/site-packages/gunicorn/workers/base.py", line 126, in init_process
    self.load_wsgi()
  File "/home/ubuntu/Desktop/ece1779/databases/venv/lib/python3.5/site-packages/gunicorn/workers/base.py", line 136, in load_wsgi
    self.wsgi = self.app.wsgi()
  File "/home/ubuntu/Desktop/ece1779/databases/venv/lib/python3.5/site-packages/gunicorn/app/base.py", line 67, in wsgi
    self.callable = self.load()
  File "/home/ubuntu/Desktop/ece1779/databases/venv/lib/python3.5/site-packages/gunicorn/app/wsgiapp.py", line 65, in load
    return self.load_wsgiapp()
  File "/home/ubuntu/Desktop/ece1779/databases/venv/lib/python3.5/site-packages/gunicorn/app/wsgiapp.py", line 52, in load_wsgiapp
    return util.import_app(self.app_uri)
  File "/home/ubuntu/Desktop/ece1779/databases/venv/lib/python3.5/site-packages/gunicorn/util.py", line 357, in import_app
    __import__(module)
  File "/home/ubuntu/Desktop/ece1779/manager_UI/app/__init__.py", line 9, in <module>
    from app import workers
  File "/home/ubuntu/Desktop/ece1779/manager_UI/app/workers.py", line 113
    EndTime = datetime.utcnow() -ß timedelta(seconds=1 * 60),
                                           ^
SyntaxError: invalid syntax
[2019-03-12 16:56:39 +0000] [6842] [INFO] Worker exiting (pid: 6842)
[2019-03-12 16:56:39 +0000] [6826] [INFO] Shutting down: Master
[2019-03-12 16:56:39 +0000] [6826] [INFO] Reason: Worker failed to boot.
[2019-03-12 16:56:55 +0000] [6848] [INFO] Starting gunicorn 19.6.0
[2019-03-12 16:56:55 +0000] [6848] [INFO] Listening at: http://0.0.0.0:5000 (6848)
[2019-03-12 16:56:55 +0000] [6848] [INFO] Using worker: sync
[2019-03-12 16:56:55 +0000] [6851] [INFO] Booting worker with pid: 6851
[2019-03-12 16:56:59,645] ERROR in app: Exception on /ec2_worker/i-073bb9dc0fa33d685 [GET]
Traceback (most recent call last):
  File "/home/ubuntu/Desktop/ece1779/databases/venv/lib/python3.5/site-packages/flask/app.py", line 1982, in wsgi_app
    response = self.full_dispatch_request()
  File "/home/ubuntu/Desktop/ece1779/databases/venv/lib/python3.5/site-packages/flask/app.py", line 1614, in full_dispatch_request
    rv = self.handle_user_exception(e)
  File "/home/ubuntu/Desktop/ece1779/databases/venv/lib/python3.5/site-packages/flask/app.py", line 1517, in handle_user_exception
    reraise(exc_type, exc_value, tb)
  File "/home/ubuntu/Desktop/ece1779/databases/venv/lib/python3.5/site-packages/flask/_compat.py", line 33, in reraise
    raise value
  File "/home/ubuntu/Desktop/ece1779/databases/venv/lib/python3.5/site-packages/flask/app.py", line 1612, in full_dispatch_request
    rv = self.dispatch_request()
  File "/home/ubuntu/Desktop/ece1779/databases/venv/lib/python3.5/site-packages/flask/app.py", line 1598, in dispatch_request
    return self.view_functions[rule.endpoint](**req.view_args)
  File "/home/ubuntu/Desktop/ece1779/manager_UI/app/workers.py", line 115, in ec2_view
    statistics = ['sum']
  File "/home/ubuntu/Desktop/ece1779/databases/venv/lib/python3.5/site-packages/botocore/client.py", line 357, in _api_call
    return self._make_api_call(operation_name, kwargs)
  File "/home/ubuntu/Desktop/ece1779/databases/venv/lib/python3.5/site-packages/botocore/client.py", line 634, in _make_api_call
    api_params, operation_model, context=request_context)
  File "/home/ubuntu/Desktop/ece1779/databases/venv/lib/python3.5/site-packages/botocore/client.py", line 682, in _convert_to_request_dict
    api_params, operation_model)
  File "/home/ubuntu/Desktop/ece1779/databases/venv/lib/python3.5/site-packages/botocore/validate.py", line 297, in serialize_to_request
    raise ParamValidationError(report=report.generate_report())
botocore.exceptions.ParamValidationError: Parameter validation failed:
Unknown parameter in input: "Dimension", must be one of: Namespace, MetricName, Dimensions, StartTime, EndTime, Period, Statistics, ExtendedStatistics, Unit
Unknown parameter in input: "statistics", must be one of: Namespace, MetricName, Dimensions, StartTime, EndTime, Period, Statistics, ExtendedStatistics, Unit
[2019-03-12 16:57:30 +0000] [6848] [CRITICAL] WORKER TIMEOUT (pid:6851)
[2019-03-12 16:57:30 +0000] [6851] [INFO] Worker exiting (pid: 6851)
[2019-03-12 16:57:30 +0000] [6855] [INFO] Booting worker with pid: 6855
[2019-03-12 16:57:47 +0000] [6848] [INFO] Handling signal: int
[2019-03-12 16:57:47 +0000] [6855] [INFO] Worker exiting (pid: 6855)
[2019-03-12 16:57:48 +0000] [6848] [INFO] Shutting down: Master
[2019-03-12 17:13:00 +0000] [7067] [INFO] Starting gunicorn 19.6.0
[2019-03-12 17:13:00 +0000] [7067] [INFO] Listening at: http://0.0.0.0:5000 (7067)
[2019-03-12 17:13:00 +0000] [7067] [INFO] Using worker: sync
[2019-03-12 17:13:00 +0000] [7070] [INFO] Booting worker with pid: 7070
[2019-03-12 17:14:05 +0000] [7067] [CRITICAL] WORKER TIMEOUT (pid:7070)
[2019-03-12 17:14:05 +0000] [7070] [INFO] Worker exiting (pid: 7070)
[2019-03-12 17:14:05 +0000] [7076] [INFO] Booting worker with pid: 7076
[2019-03-12 17:14:22 +0000] [7067] [INFO] Handling signal: int
[2019-03-12 17:14:22 +0000] [7076] [INFO] Worker exiting (pid: 7076)
[2019-03-12 17:14:22 +0000] [7067] [INFO] Shutting down: Master
[2019-03-12 17:53:01 +0000] [7434] [INFO] Starting gunicorn 19.6.0
[2019-03-12 17:53:01 +0000] [7434] [ERROR] Connection in use: ('0.0.0.0', 5000)
[2019-03-12 17:53:01 +0000] [7434] [ERROR] Retrying in 1 second.
[2019-03-12 17:53:02 +0000] [7434] [ERROR] Connection in use: ('0.0.0.0', 5000)
[2019-03-12 17:53:02 +0000] [7434] [ERROR] Retrying in 1 second.
[2019-03-12 17:53:03 +0000] [7434] [ERROR] Connection in use: ('0.0.0.0', 5000)
[2019-03-12 17:53:03 +0000] [7434] [ERROR] Retrying in 1 second.
[2019-03-12 17:53:04 +0000] [7434] [ERROR] Connection in use: ('0.0.0.0', 5000)
[2019-03-12 17:53:04 +0000] [7434] [ERROR] Retrying in 1 second.
[2019-03-12 17:53:05 +0000] [7434] [ERROR] Connection in use: ('0.0.0.0', 5000)
[2019-03-12 17:53:05 +0000] [7434] [ERROR] Retrying in 1 second.
[2019-03-12 17:53:06 +0000] [7434] [ERROR] Can't connect to ('0.0.0.0', 5000)
